mplus_output/uni-36-MHAS_W3.out
Mplus VERSION 8.1 (Mac)
MUTHEN & MUTHEN
05/27/2020  10:28 PM

INPUT INSTRUCTIONS

  DATA:
  FILE = "uni-36-MHAS_W3.dat";

  VARIABLE:
  NAMES = mplusid UDAY UMON UYER UWR1 UWR2 UWR3 UANI UNUM2 UFCO3 UFRE2 UWD UVSC;
   MISSING=.;
   CATEGORICAL ARE all; idvariable = mplusid;
  ANALYSIS:
  estimator = wlsmv; coverage=0;
  MODEL:
  g by UDAY * ;
   g by UMON * ;
   g by UYER * ;
   g by UANI * ;
   g by UWR1 * ;
   g by UWR2 * ;
   g by UWR3 * ;
   g by UWD * ;
   g by UVSC * ;
   g by UNUM2 * ;
   g by UFCO3 * ;
   g by UFRE2 * ;
   g @ 1;

  OUTPUT:
  standardized; svalues;



*** WARNING
  Data set contains cases with missing on all variables.
  These cases were not included in the analysis.
  Number of cases with missing on all variables:  101
   1 WARNING(S) FOUND IN THE INPUT INSTRUCTIONS




SUMMARY OF ANALYSIS

Number of groups                                                 1
Number of observations                                        5457

Number of dependent variables                                   12
Number of independent variables                                  0
Number of continuous latent variables                            1

Observed dependent variables

  Binary and ordered categorical (ordinal)
   UDAY        UMON        UYER        UWR1        UWR2        UWR3
   UANI        UNUM2       UFCO3       UFRE2       UWD         UVSC

Continuous latent variables
   G

Variables with special functions

  ID variable           MPLUSID

Estimator                                                    WLSMV
Maximum number of iterations                                  1000
Convergence criterion                                    0.500D-04
Maximum number of steepest descent iterations                   20
Maximum number of iterations for H1                           2000
Convergence criterion for H1                             0.100D-03
Parameterization                                             DELTA
Link                                                        PROBIT

Input data file(s)
  uni-36-MHAS_W3.dat

Input data format  FREE


SUMMARY OF DATA

     Number of missing data patterns            43


COVARIANCE COVERAGE OF DATA

Minimum covariance coverage value   0.000


     PROPORTION OF DATA PRESENT


           Covariance Coverage
              UDAY          UMON          UYER          UWR1          UWR2
              ________      ________      ________      ________      ________
 UDAY           0.997
 UMON           0.995         0.997
 UYER           0.995         0.996         0.997
 UWR1           0.993         0.992         0.992         0.996
 UWR2           0.993         0.992         0.992         0.995         0.996
 UWR3           0.992         0.992         0.992         0.995         0.995
 UANI           0.992         0.991         0.991         0.992         0.992
 UNUM2          0.973         0.972         0.972         0.973         0.973
 UFCO3          0.959         0.958         0.958         0.958         0.958
 UFRE2          0.953         0.953         0.952         0.953         0.953
 UWD            0.990         0.990         0.990         0.993         0.993
 UVSC           0.963         0.962         0.962         0.962         0.962


           Covariance Coverage
              UWR3          UANI          UNUM2         UFCO3         UFRE2
              ________      ________      ________      ________      ________
 UWR3           0.995
 UANI           0.991         0.995
 UNUM2          0.973         0.973         0.976
 UFCO3          0.958         0.958         0.946         0.961
 UFRE2          0.952         0.953         0.941         0.955         0.956
 UWD            0.993         0.989         0.971         0.957         0.951
 UVSC           0.962         0.963         0.949         0.952         0.947


           Covariance Coverage
              UWD           UVSC
              ________      ________
 UWD            0.993
 UVSC           0.961         0.965


UNIVARIATE PROPORTIONS AND COUNTS FOR CATEGORICAL VARIABLES

    UDAY
      Category 1    0.192         1042.000
      Category 2    0.808         4399.000
    UMON
      Category 1    0.057          309.000
      Category 2    0.943         5129.000
    UYER
      Category 1    0.098          531.000
      Category 2    0.902         4907.000
    UWR1
      Category 1    0.006           31.000
      Category 2    0.016           86.000
      Category 3    0.061          331.000
      Category 4    0.177          963.000
      Category 5    0.278         1510.000
      Category 6    0.277         1503.000
      Category 7    0.147          799.000
      Category 8    0.034          184.000
      Category 9    0.005           26.000
    UWR2
      Category 1    0.004           20.000
      Category 2    0.003           19.000
      Category 3    0.014           75.000
      Category 4    0.066          361.000
      Category 5    0.176          958.000
      Category 6    0.284         1542.000
      Category 7    0.271         1474.000
      Category 8    0.142          773.000
      Category 9    0.039          211.000
    UWR3
      Category 1    0.008           41.000
      Category 2    0.002           13.000
      Category 3    0.013           73.000
      Category 4    0.034          185.000
      Category 5    0.092          497.000
      Category 6    0.204         1106.000
      Category 7    0.301         1637.000
      Category 8    0.227         1231.000
      Category 9    0.119          648.000
    UANI
      Category 1    0.003           18.000
      Category 2    0.029          159.000
      Category 3    0.087          473.000
      Category 4    0.174          946.000
      Category 5    0.230         1250.000
      Category 6    0.143          778.000
      Category 7    0.169          919.000
      Category 8    0.097          527.000
      Category 9    0.042          228.000
      Category 10    0.024          129.000
    UNUM2
      Category 1    0.090          480.000
      Category 2    0.910         4844.000
    UFCO3
      Category 1    0.004           23.000
      Category 2    0.004           21.000
      Category 3    0.006           34.000
      Category 4    0.013           67.000
      Category 5    0.035          185.000
      Category 6    0.095          500.000
      Category 7    0.842         4416.000
    UFRE2
      Category 1    0.025          131.000
      Category 2    0.012           61.000
      Category 3    0.027          140.000
      Category 4    0.038          196.000
      Category 5    0.110          572.000
      Category 6    0.206         1072.000
      Category 7    0.584         3043.000
    UWD
      Category 1    0.030          165.000
      Category 2    0.014           75.000
      Category 3    0.036          196.000
      Category 4    0.083          448.000
      Category 5    0.170          922.000
      Category 6    0.236         1280.000
      Category 7    0.222         1201.000
      Category 8    0.147          798.000
      Category 9    0.062          334.000
    UVSC
      Category 1    0.015           78.000
      Category 2    0.029          152.000
      Category 3    0.054          285.000
      Category 4    0.084          441.000
      Category 5    0.126          665.000
      Category 6    0.136          714.000
      Category 7    0.132          696.000
      Category 8    0.132          695.000
      Category 9    0.110          577.000
      Category 10    0.183          965.000



THE MODEL ESTIMATION TERMINATED NORMALLY



MODEL FIT INFORMATION

Number of Free Parameters                       78

Chi-Square Test of Model Fit

          Value                           3855.612*
          Degrees of Freedom                    54
          P-Value                           0.0000

*   The chi-square value for MLM, MLMV, MLR, ULSMV, WLSM and WLSMV cannot be used
    for chi-square difference testing in the regular way.  MLM, MLR and WLSM
    chi-square difference testing is described on the Mplus website.  MLMV, WLSMV,
